2024-08-08 17:28:12.764 | ERROR    | app.exceptions.exception_handler:global_exception_handler:98 - 系统异常,   + Exception Group Traceback (most recent call last):
  |   File "D:\bread\.venv\Lib\site-packages\starlette\_utils.py", line 87, in collapse_excgroups
  |     yield
  |   File "D:\bread\.venv\Lib\site-packages\starlette\middleware\base.py", line 190, in __call__
  |     async with anyio.create_task_group() as task_group:
  |   File "D:\bread\.venv\Lib\site-packages\anyio\_backends\_asyncio.py", line 680, in __aexit__
  |     raise BaseExceptionGroup(
  | ExceptionGroup: unhandled errors in a TaskGroup (1 sub-exception)
  +-+---------------- 1 ----------------
    | Traceback (most recent call last):
    |   File "D:\bread\.venv\Lib\site-packages\starlette\middleware\errors.py", line 164, in __call__
    |     await self.app(scope, receive, _send)
    |   File "D:\bread\.venv\Lib\site-packages\starlette\middleware\cors.py", line 93, in __call__
    |     await self.simple_response(scope, receive, send, request_headers=headers)
    |   File "D:\bread\.venv\Lib\site-packages\starlette\middleware\cors.py", line 148, in simple_response
    |     await self.app(scope, receive, send)
    |   File "D:\bread\.venv\Lib\site-packages\starlette\middleware\base.py", line 189, in __call__
    |     with collapse_excgroups():
    |   File "C:\Users\v_wieszheng\AppData\Local\Programs\Python\Python312\Lib\contextlib.py", line 155, in __exit__
    |     self.gen.throw(value)
    |   File "D:\bread\.venv\Lib\site-packages\starlette\_utils.py", line 93, in collapse_excgroups
    |     raise exc
    |   File "D:\bread\.venv\Lib\site-packages\starlette\middleware\base.py", line 191, in __call__
    |     response = await self.dispatch_func(request, call_next)
    |                ^^^^^^^^^^^^^^^^^^^^^^^^^^^^^^^^^^^^^^^^^^^^
    |   File "D:\bread\app\middlewares\middlewares.py", line 64, in dispatch
    |     response = await call_next(request)
    |                ^^^^^^^^^^^^^^^^^^^^^^^^
    |   File "D:\bread\.venv\Lib\site-packages\starlette\middleware\base.py", line 165, in call_next
    |     raise app_exc
    |   File "D:\bread\.venv\Lib\site-packages\starlette\middleware\base.py", line 151, in coro
    |     await self.app(scope, receive_or_disconnect, send_no_error)
    |   File "D:\bread\.venv\Lib\site-packages\starlette\middleware\exceptions.py", line 65, in __call__
    |     await wrap_app_handling_exceptions(self.app, conn)(scope, receive, send)
    |   File "D:\bread\.venv\Lib\site-packages\starlette\_exception_handler.py", line 64, in wrapped_app
    |     raise exc
    |   File "D:\bread\.venv\Lib\site-packages\starlette\_exception_handler.py", line 53, in wrapped_app
    |     await app(scope, receive, sender)
    |   File "D:\bread\.venv\Lib\site-packages\starlette\routing.py", line 756, in __call__
    |     await self.middleware_stack(scope, receive, send)
    |   File "D:\bread\.venv\Lib\site-packages\starlette\routing.py", line 776, in app
    |     await route.handle(scope, receive, send)
    |   File "D:\bread\.venv\Lib\site-packages\starlette\routing.py", line 297, in handle
    |     await self.app(scope, receive, send)
    |   File "D:\bread\.venv\Lib\site-packages\starlette\routing.py", line 77, in app
    |     await wrap_app_handling_exceptions(app, request)(scope, receive, send)
    |   File "D:\bread\.venv\Lib\site-packages\starlette\_exception_handler.py", line 64, in wrapped_app
    |     raise exc
    |   File "D:\bread\.venv\Lib\site-packages\starlette\_exception_handler.py", line 53, in wrapped_app
    |     await app(scope, receive, sender)
    |   File "D:\bread\.venv\Lib\site-packages\starlette\routing.py", line 72, in app
    |     response = await func(request)
    |                ^^^^^^^^^^^^^^^^^^^
    |   File "D:\bread\.venv\Lib\site-packages\fastapi\routing.py", line 269, in app
    |     solved_result = await solve_dependencies(
    |                     ^^^^^^^^^^^^^^^^^^^^^^^^^
    |   File "D:\bread\.venv\Lib\site-packages\fastapi\dependencies\utils.py", line 602, in solve_dependencies
    |     solved = await run_in_threadpool(call, **sub_values)
    |              ^^^^^^^^^^^^^^^^^^^^^^^^^^^^^^^^^^^^^^^^^^^
    |   File "D:\bread\.venv\Lib\site-packages\starlette\concurrency.py", line 42, in run_in_threadpool
    |     return await anyio.to_thread.run_sync(func, *args)
    |            ^^^^^^^^^^^^^^^^^^^^^^^^^^^^^^^^^^^^^^^^^^^
    |   File "D:\bread\.venv\Lib\site-packages\anyio\to_thread.py", line 56, in run_sync
    |     return await get_async_backend().run_sync_in_worker_thread(
    |            ^^^^^^^^^^^^^^^^^^^^^^^^^^^^^^^^^^^^^^^^^^^^^^^^^^^^
    |   File "D:\bread\.venv\Lib\site-packages\anyio\_backends\_asyncio.py", line 2177, in run_sync_in_worker_thread
    |     return await future
    |            ^^^^^^^^^^^^
    |   File "D:\bread\.venv\Lib\site-packages\anyio\_backends\_asyncio.py", line 859, in run
    |     result = context.run(func, *args)
    |              ^^^^^^^^^^^^^^^^^^^^^^^^
    |   File "C:\Users\v_wieszheng\AppData\Local\Programs\Python\Python312\Lib\typing.py", line 525, in __new__
    |     raise TypeError("Any cannot be instantiated")
    | TypeError: Any cannot be instantiated
    +------------------------------------

During handling of the above exception, another exception occurred:

Traceback (most recent call last):
  File "D:\bread\.venv\Lib\site-packages\starlette\middleware\errors.py", line 164, in __call__
    await self.app(scope, receive, _send)
  File "D:\bread\.venv\Lib\site-packages\starlette\middleware\cors.py", line 93, in __call__
    await self.simple_response(scope, receive, send, request_headers=headers)
  File "D:\bread\.venv\Lib\site-packages\starlette\middleware\cors.py", line 148, in simple_response
    await self.app(scope, receive, send)
  File "D:\bread\.venv\Lib\site-packages\starlette\middleware\base.py", line 189, in __call__
    with collapse_excgroups():
  File "C:\Users\v_wieszheng\AppData\Local\Programs\Python\Python312\Lib\contextlib.py", line 155, in __exit__
    self.gen.throw(value)
  File "D:\bread\.venv\Lib\site-packages\starlette\_utils.py", line 93, in collapse_excgroups
    raise exc
  File "D:\bread\.venv\Lib\site-packages\starlette\middleware\base.py", line 191, in __call__
    response = await self.dispatch_func(request, call_next)
               ^^^^^^^^^^^^^^^^^^^^^^^^^^^^^^^^^^^^^^^^^^^^
  File "D:\bread\app\middlewares\middlewares.py", line 64, in dispatch
    response = await call_next(request)
               ^^^^^^^^^^^^^^^^^^^^^^^^
  File "D:\bread\.venv\Lib\site-packages\starlette\middleware\base.py", line 165, in call_next
    raise app_exc
  File "D:\bread\.venv\Lib\site-packages\starlette\middleware\base.py", line 151, in coro
    await self.app(scope, receive_or_disconnect, send_no_error)
  File "D:\bread\.venv\Lib\site-packages\starlette\middleware\exceptions.py", line 65, in __call__
    await wrap_app_handling_exceptions(self.app, conn)(scope, receive, send)
  File "D:\bread\.venv\Lib\site-packages\starlette\_exception_handler.py", line 64, in wrapped_app
    raise exc
  File "D:\bread\.venv\Lib\site-packages\starlette\_exception_handler.py", line 53, in wrapped_app
    await app(scope, receive, sender)
  File "D:\bread\.venv\Lib\site-packages\starlette\routing.py", line 756, in __call__
    await self.middleware_stack(scope, receive, send)
  File "D:\bread\.venv\Lib\site-packages\starlette\routing.py", line 776, in app
    await route.handle(scope, receive, send)
  File "D:\bread\.venv\Lib\site-packages\starlette\routing.py", line 297, in handle
    await self.app(scope, receive, send)
  File "D:\bread\.venv\Lib\site-packages\starlette\routing.py", line 77, in app
    await wrap_app_handling_exceptions(app, request)(scope, receive, send)
  File "D:\bread\.venv\Lib\site-packages\starlette\_exception_handler.py", line 64, in wrapped_app
    raise exc
  File "D:\bread\.venv\Lib\site-packages\starlette\_exception_handler.py", line 53, in wrapped_app
    await app(scope, receive, sender)
  File "D:\bread\.venv\Lib\site-packages\starlette\routing.py", line 72, in app
    response = await func(request)
               ^^^^^^^^^^^^^^^^^^^
  File "D:\bread\.venv\Lib\site-packages\fastapi\routing.py", line 269, in app
    solved_result = await solve_dependencies(
                    ^^^^^^^^^^^^^^^^^^^^^^^^^
  File "D:\bread\.venv\Lib\site-packages\fastapi\dependencies\utils.py", line 602, in solve_dependencies
    solved = await run_in_threadpool(call, **sub_values)
             ^^^^^^^^^^^^^^^^^^^^^^^^^^^^^^^^^^^^^^^^^^^
  File "D:\bread\.venv\Lib\site-packages\starlette\concurrency.py", line 42, in run_in_threadpool
    return await anyio.to_thread.run_sync(func, *args)
           ^^^^^^^^^^^^^^^^^^^^^^^^^^^^^^^^^^^^^^^^^^^
  File "D:\bread\.venv\Lib\site-packages\anyio\to_thread.py", line 56, in run_sync
    return await get_async_backend().run_sync_in_worker_thread(
           ^^^^^^^^^^^^^^^^^^^^^^^^^^^^^^^^^^^^^^^^^^^^^^^^^^^^
  File "D:\bread\.venv\Lib\site-packages\anyio\_backends\_asyncio.py", line 2177, in run_sync_in_worker_thread
    return await future
           ^^^^^^^^^^^^
  File "D:\bread\.venv\Lib\site-packages\anyio\_backends\_asyncio.py", line 859, in run
    result = context.run(func, *args)
             ^^^^^^^^^^^^^^^^^^^^^^^^
  File "C:\Users\v_wieszheng\AppData\Local\Programs\Python\Python312\Lib\typing.py", line 525, in __new__
    raise TypeError("Any cannot be instantiated")
TypeError: Any cannot be instantiated

